2023-05-19 10:17:28,952 INFO    MainThread:1132 [internal.py:wandb_internal():93] W&B internal server running at pid: 1132, started at: 2023-05-19 10:17:28.951814
2023-05-19 10:17:28,955 INFO    WriterThread:1132 [datastore.py:open_for_write():75] open: /kaggle/working/multi_label/exp25_2022_1st_like_focalloss_prob_label/wandb/run-20230519_101727-326llrxh/run-326llrxh.wandb
2023-05-19 10:17:28,957 DEBUG   SenderThread:1132 [sender.py:send():236] send: header
2023-05-19 10:17:28,957 DEBUG   SenderThread:1132 [sender.py:send():236] send: run
2023-05-19 10:17:29,319 ERROR   SenderThread:1132 [internal_api.py:execute():161] 400 response executing GraphQL.
2023-05-19 10:17:29,319 ERROR   SenderThread:1132 [internal_api.py:execute():162] {"errors":[{"message":"invalid parameters: 128 character limit exceeded for GroupName: add union(20,21,22,xeno)|loss=focalloss|fine-tuning(exp-10)|2022_1st_like|(\u003cin_duration):primary=1,secondary=1|(\u003ein_duration):primary=0.995,secondary=0.5","path":["upsertBucket"]}],"data":{"upsertBucket":null}}
2023-05-19 10:17:29,956 INFO    HandlerThread:1132 [handler.py:finish():806] shutting down handler
2023-05-19 10:17:29,967 INFO    WriterThread:1132 [datastore.py:close():279] close: /kaggle/working/multi_label/exp25_2022_1st_like_focalloss_prob_label/wandb/run-20230519_101727-326llrxh/run-326llrxh.wandb
2023-05-19 10:17:29,967 ERROR   MainThread:1132 [internal.py:wandb_internal():165] Thread SenderThread:
Traceback (most recent call last):
  File "/opt/conda/lib/python3.7/site-packages/wandb/apis/normalize.py", line 25, in wrapper
    return func(*args, **kwargs)
  File "/opt/conda/lib/python3.7/site-packages/wandb/sdk/internal/internal_api.py", line 1341, in upsert_run
    response = self.gql(mutation, variable_values=variable_values, **kwargs)
  File "/opt/conda/lib/python3.7/site-packages/wandb/sdk/lib/retry.py", line 108, in __call__
    result = self._call_fn(*args, **kwargs)
  File "/opt/conda/lib/python3.7/site-packages/wandb/sdk/internal/internal_api.py", line 158, in execute
    return self.client.execute(*args, **kwargs)
  File "/opt/conda/lib/python3.7/site-packages/wandb/vendor/gql-0.2.0/wandb_gql/client.py", line 52, in execute
    result = self._get_result(document, *args, **kwargs)
  File "/opt/conda/lib/python3.7/site-packages/wandb/vendor/gql-0.2.0/wandb_gql/client.py", line 60, in _get_result
    return self.transport.execute(document, *args, **kwargs)
  File "/opt/conda/lib/python3.7/site-packages/wandb/vendor/gql-0.2.0/wandb_gql/transport/requests.py", line 39, in execute
    request.raise_for_status()
  File "/opt/conda/lib/python3.7/site-packages/requests/models.py", line 1021, in raise_for_status
    raise HTTPError(http_error_msg, response=self)
requests.exceptions.HTTPError: 400 Client Error: Bad Request for url: https://api.wandb.ai/graphql

During handling of the above exception, another exception occurred:

Traceback (most recent call last):
  File "/opt/conda/lib/python3.7/site-packages/wandb/sdk/internal/internal_util.py", line 51, in run
    self._run()
  File "/opt/conda/lib/python3.7/site-packages/wandb/sdk/internal/internal_util.py", line 102, in _run
    self._process(record)
  File "/opt/conda/lib/python3.7/site-packages/wandb/sdk/internal/internal.py", line 310, in _process
    self._sm.send(record)
  File "/opt/conda/lib/python3.7/site-packages/wandb/sdk/internal/sender.py", line 238, in send
    send_handler(record)
  File "/opt/conda/lib/python3.7/site-packages/wandb/sdk/internal/sender.py", line 696, in send_run
    self._init_run(run, config_value_dict)
  File "/opt/conda/lib/python3.7/site-packages/wandb/sdk/internal/sender.py", line 734, in _init_run
    commit=run.git.last_commit or None,
  File "/opt/conda/lib/python3.7/site-packages/wandb/apis/normalize.py", line 27, in wrapper
    raise CommError(err.response, err)
wandb.errors.CommError: <Response [400]>
2023-05-19 10:17:31,983 INFO    MainThread:1132 [internal.py:handle_exit():80] Internal process exited
