#########################
#### Training
#### Fold: 1 | Image Size: (224, 313) | Model: tf_efficientnet_b1_ns | Batch Size: 128 | Scheduler: cos
#### Num Train: 19,627 | Num Valid: 3,381



























































































100%|██████████| 154/154 [03:07<00:00,  1.22s/it]











100%|██████████| 27/27 [00:25<00:00,  1.07it/s]
Epoch: 1 | Train Loss: 0.20727321039280527 | Val Loss: 0.007314775070106542 | Val Padded_cmAP : 0.47960454533713326




  4%|▍         | 6/154 [00:11<03:38,  1.47s/it]
Traceback (most recent call last):
  File "/opt/conda/lib/python3.7/site-packages/IPython/core/interactiveshell.py", line 3552, in run_code
    exec(code_obj, self.user_global_ns, self.user_ns)
  File "/tmp/ipykernel_28972/3835926567.py", line 98, in <module>
    inputs, targets = inputs.to(device), sample_info['target'].to(device) #sample_info['multi_label_target'].to(device)
KeyboardInterrupt
During handling of the above exception, another exception occurred:
Traceback (most recent call last):
  File "/opt/conda/lib/python3.7/site-packages/IPython/core/interactiveshell.py", line 2098, in showtraceback
    stb = value._render_traceback_()
AttributeError: 'KeyboardInterrupt' object has no attribute '_render_traceback_'
During handling of the above exception, another exception occurred:
Traceback (most recent call last):
  File "/opt/conda/lib/python3.7/site-packages/IPython/core/ultratb.py", line 1101, in get_records
    return _fixed_getinnerframes(etb, number_of_lines_of_context, tb_offset)
  File "/opt/conda/lib/python3.7/site-packages/IPython/core/ultratb.py", line 248, in wrapped
    return f(*args, **kwargs)
  File "/opt/conda/lib/python3.7/site-packages/IPython/core/ultratb.py", line 281, in _fixed_getinnerframes
    records = fix_frame_records_filenames(inspect.getinnerframes(etb, context))
  File "/opt/conda/lib/python3.7/inspect.py", line 1502, in getinnerframes
    frameinfo = (tb.tb_frame,) + getframeinfo(tb, context)
  File "/opt/conda/lib/python3.7/inspect.py", line 1460, in getframeinfo
    filename = getsourcefile(frame) or getfile(frame)
  File "/opt/conda/lib/python3.7/inspect.py", line 696, in getsourcefile
    if getattr(getmodule(object, filename), '__loader__', None) is not None:
  File "/opt/conda/lib/python3.7/inspect.py", line 739, in getmodule
    f = getabsfile(module)
  File "/opt/conda/lib/python3.7/inspect.py", line 708, in getabsfile
    _filename = getsourcefile(object) or getfile(object)
  File "/opt/conda/lib/python3.7/inspect.py", line 693, in getsourcefile
    if os.path.exists(filename):
  File "/opt/conda/lib/python3.7/genericpath.py", line 19, in exists
    os.stat(path)
  4%|▍         | 6/154 [00:11<03:38,  1.47s/it]Exception ignored in: <function _MultiProcessingDataLoaderIter.__del__ at 0x7fc20123d830>
Traceback (most recent call last):
  File "/opt/conda/lib/python3.7/site-packages/torch/utils/data/dataloader.py", line 1466, in __del__
    self._shutdown_workers()
  File "/opt/conda/lib/python3.7/site-packages/torch/utils/data/dataloader.py", line 1430, in _shutdown_workers
    w.join(timeout=_utils.MP_STATUS_CHECK_INTERVAL)
  File "/opt/conda/lib/python3.7/multiprocessing/process.py", line 140, in join
    res = self._popen.wait(timeout)
  File "/opt/conda/lib/python3.7/multiprocessing/popen_fork.py", line 45, in wait
    if not wait([self.sentinel], timeout):
  File "/opt/conda/lib/python3.7/multiprocessing/connection.py", line 921, in wait
    ready = selector.select(timeout)
  File "/opt/conda/lib/python3.7/selectors.py", line 415, in select
    fd_event_list = self._selector.poll(timeout)
KeyboardInterrupt:
  4%|▍         | 6/154 [00:14<05:51,  2.38s/it]
Process wandb_internal:
Traceback (most recent call last):
  File "/opt/conda/lib/python3.7/multiprocessing/process.py", line 297, in _bootstrap
    self.run()
  File "/opt/conda/lib/python3.7/multiprocessing/process.py", line 99, in run
    self._target(*self._args, **self._kwargs)
  File "/opt/conda/lib/python3.7/site-packages/wandb/sdk/internal/internal.py", line 160, in wandb_internal
    thread.join()
  File "/opt/conda/lib/python3.7/threading.py", line 1044, in join
    self._wait_for_tstate_lock()
  File "/opt/conda/lib/python3.7/threading.py", line 1060, in _wait_for_tstate_lock
    elif lock.acquire(block, timeout):
KeyboardInterrupt
Exception in thread ChkStopThr:
Traceback (most recent call last):
  File "/opt/conda/lib/python3.7/threading.py", line 926, in _bootstrap_inner
    self.run()
  File "/opt/conda/lib/python3.7/threading.py", line 870, in run
    self._target(*self._args, **self._kwargs)
  File "/opt/conda/lib/python3.7/site-packages/wandb/sdk/wandb_run.py", line 170, in check_status
    status_response = self._interface.communicate_stop_status()
  File "/opt/conda/lib/python3.7/site-packages/wandb/sdk/interface/interface.py", line 127, in communicate_stop_status
    resp = self._communicate_stop_status(status)
  File "/opt/conda/lib/python3.7/site-packages/wandb/sdk/interface/interface_shared.py", line 395, in _communicate_stop_status
    resp = self._communicate(req, local=True)
  File "/opt/conda/lib/python3.7/site-packages/wandb/sdk/interface/interface_shared.py", line 226, in _communicate
    return self._communicate_async(rec, local=local).get(timeout=timeout)
  File "/opt/conda/lib/python3.7/site-packages/wandb/sdk/interface/interface_shared.py", line 231, in _communicate_async
    raise Exception("The wandb backend process has shutdown")
Exception: The wandb backend process has shutdown
Exception in thread NetStatThr:
Traceback (most recent call last):
  File "/opt/conda/lib/python3.7/threading.py", line 926, in _bootstrap_inner
    self.run()
  File "/opt/conda/lib/python3.7/threading.py", line 870, in run
    self._target(*self._args, **self._kwargs)
  File "/opt/conda/lib/python3.7/site-packages/wandb/sdk/wandb_run.py", line 152, in check_network_status
    status_response = self._interface.communicate_network_status()
  File "/opt/conda/lib/python3.7/site-packages/wandb/sdk/interface/interface.py", line 138, in communicate_network_status
    resp = self._communicate_network_status(status)
  File "/opt/conda/lib/python3.7/site-packages/wandb/sdk/interface/interface_shared.py", line 405, in _communicate_network_status
    resp = self._communicate(req, local=True)
  File "/opt/conda/lib/python3.7/site-packages/wandb/sdk/interface/interface_shared.py", line 226, in _communicate
    return self._communicate_async(rec, local=local).get(timeout=timeout)
  File "/opt/conda/lib/python3.7/site-packages/wandb/sdk/interface/interface_shared.py", line 231, in _communicate_async
    raise Exception("The wandb backend process has shutdown")
