
  0%|          | 0/154 [00:00<?, ?it/s]
load pre-trained model :  /kaggle/working/WSL/exp10_softmax_model/fold-0.pth
_IncompatibleKeys(missing_keys=['bn0.weight', 'bn0.bias', 'bn0.running_mean', 'bn0.running_var', 'fc1.weight', 'fc1.bias', 'att_block.att.weight', 'att_block.att.bias', 'att_block.cla.weight', 'att_block.cla.bias'], unexpected_keys=[])
#########################
#### Training
#### Fold: 1 | Image Size: (224, 313) | Model: tf_efficientnet_b1_ns | Batch Size: 128 | Scheduler: cos
























































































100%|██████████| 154/154 [03:06<00:00,  1.21s/it]






100%|██████████| 27/27 [00:14<00:00,  1.82it/s]
Epoch: 1 | Train Loss: 0.31208165131460924 | Val Loss: 0.008995135004321734 | Val Padded_cmAP : 0.4797111528527003


























































































100%|██████████| 154/154 [03:04<00:00,  1.20s/it]






100%|██████████| 27/27 [00:14<00:00,  1.82it/s]
Epoch: 2 | Train Loss: 0.009026446978428535 | Val Loss: 0.009220743551850319 | Val Padded_cmAP : 0.48131842038445993
  0%|          | 0/154 [00:00<?, ?it/s]
Traceback (most recent call last):
  File "/opt/conda/lib/python3.7/site-packages/IPython/core/interactiveshell.py", line 3552, in run_code
    exec(code_obj, self.user_global_ns, self.user_ns)
  File "/tmp/ipykernel_18533/364853370.py", line 97, in <module>
    for batch_idx, (inputs, sample_info) in enumerate(tqdm(train_dataloader)):
  File "/opt/conda/lib/python3.7/site-packages/tqdm/std.py", line 1195, in __iter__
    for obj in iterable:
  File "/opt/conda/lib/python3.7/site-packages/torch/utils/data/dataloader.py", line 628, in __next__
    data = self._next_data()
  File "/opt/conda/lib/python3.7/site-packages/torch/utils/data/dataloader.py", line 1316, in _next_data
    idx, data = self._get_data()
  File "/opt/conda/lib/python3.7/site-packages/torch/utils/data/dataloader.py", line 1282, in _get_data
    success, data = self._try_get_data()
  File "/opt/conda/lib/python3.7/site-packages/torch/utils/data/dataloader.py", line 1120, in _try_get_data
    data = self._data_queue.get(timeout=timeout)
  File "/opt/conda/lib/python3.7/multiprocessing/queues.py", line 113, in get
    return _ForkingPickler.loads(res)
  File "/opt/conda/lib/python3.7/site-packages/torch/multiprocessing/reductions.py", line 305, in rebuild_storage_fd
    fd = df.detach()
  File "/opt/conda/lib/python3.7/multiprocessing/resource_sharer.py", line 57, in detach
    with _resource_sharer.get_connection(self._id) as conn:
  File "/opt/conda/lib/python3.7/multiprocessing/resource_sharer.py", line 87, in get_connection
    c = Client(address, authkey=process.current_process().authkey)
  File "/opt/conda/lib/python3.7/multiprocessing/connection.py", line 499, in Client
    deliver_challenge(c, authkey)
  File "/opt/conda/lib/python3.7/multiprocessing/connection.py", line 730, in deliver_challenge
    response = connection.recv_bytes(256)        # reject large message
  File "/opt/conda/lib/python3.7/multiprocessing/connection.py", line 216, in recv_bytes
    buf = self._recv_bytes(maxlength)
  File "/opt/conda/lib/python3.7/multiprocessing/connection.py", line 407, in _recv_bytes
    buf = self._recv(4)
  File "/opt/conda/lib/python3.7/multiprocessing/connection.py", line 379, in _recv
    chunk = read(handle, remaining)
KeyboardInterrupt
During handling of the above exception, another exception occurred:
Traceback (most recent call last):
  File "/opt/conda/lib/python3.7/site-packages/IPython/core/interactiveshell.py", line 2098, in showtraceback
    stb = value._render_traceback_()
AttributeError: 'KeyboardInterrupt' object has no attribute '_render_traceback_'
During handling of the above exception, another exception occurred:
Traceback (most recent call last):
  File "/opt/conda/lib/python3.7/site-packages/IPython/core/ultratb.py", line 1101, in get_records
    return _fixed_getinnerframes(etb, number_of_lines_of_context, tb_offset)
  File "/opt/conda/lib/python3.7/site-packages/IPython/core/ultratb.py", line 248, in wrapped
    return f(*args, **kwargs)
  File "/opt/conda/lib/python3.7/site-packages/IPython/core/ultratb.py", line 281, in _fixed_getinnerframes
    records = fix_frame_records_filenames(inspect.getinnerframes(etb, context))
  File "/opt/conda/lib/python3.7/inspect.py", line 1502, in getinnerframes
    frameinfo = (tb.tb_frame,) + getframeinfo(tb, context)
  File "/opt/conda/lib/python3.7/inspect.py", line 1460, in getframeinfo
    filename = getsourcefile(frame) or getfile(frame)
  File "/opt/conda/lib/python3.7/inspect.py", line 696, in getsourcefile
    if getattr(getmodule(object, filename), '__loader__', None) is not None:
  File "/opt/conda/lib/python3.7/inspect.py", line 742, in getmodule
    os.path.realpath(f)] = module.__name__
  File "/opt/conda/lib/python3.7/posixpath.py", line 395, in realpath
    path, ok = _joinrealpath(filename[:0], filename, {})
  File "/opt/conda/lib/python3.7/posixpath.py", line 429, in _joinrealpath
    if not islink(newpath):
  File "/opt/conda/lib/python3.7/posixpath.py", line 171, in islink
    st = os.lstat(path)

  0%|          | 0/154 [00:06<?, ?it/s]
Exception in thread NetStatThr:
Traceback (most recent call last):
  File "/opt/conda/lib/python3.7/threading.py", line 926, in _bootstrap_inner
    self.run()
  File "/opt/conda/lib/python3.7/threading.py", line 870, in run
    self._target(*self._args, **self._kwargs)
  File "/opt/conda/lib/python3.7/site-packages/wandb/sdk/wandb_run.py", line 152, in check_network_status
    status_response = self._interface.communicate_network_status()
  File "/opt/conda/lib/python3.7/site-packages/wandb/sdk/interface/interface.py", line 138, in communicate_network_status
    resp = self._communicate_network_status(status)
  File "/opt/conda/lib/python3.7/site-packages/wandb/sdk/interface/interface_shared.py", line 405, in _communicate_network_status
    resp = self._communicate(req, local=True)
  File "/opt/conda/lib/python3.7/site-packages/wandb/sdk/interface/interface_shared.py", line 226, in _communicate
    return self._communicate_async(rec, local=local).get(timeout=timeout)
  File "/opt/conda/lib/python3.7/site-packages/wandb/sdk/interface/interface_shared.py", line 231, in _communicate_async
    raise Exception("The wandb backend process has shutdown")
Exception: The wandb backend process has shutdown
Exception in thread ChkStopThr:
Traceback (most recent call last):
  File "/opt/conda/lib/python3.7/threading.py", line 926, in _bootstrap_inner
    self.run()
  File "/opt/conda/lib/python3.7/threading.py", line 870, in run
    self._target(*self._args, **self._kwargs)
  File "/opt/conda/lib/python3.7/site-packages/wandb/sdk/wandb_run.py", line 170, in check_status
    status_response = self._interface.communicate_stop_status()
  File "/opt/conda/lib/python3.7/site-packages/wandb/sdk/interface/interface.py", line 127, in communicate_stop_status
    resp = self._communicate_stop_status(status)
  File "/opt/conda/lib/python3.7/site-packages/wandb/sdk/interface/interface_shared.py", line 395, in _communicate_stop_status
    resp = self._communicate(req, local=True)
  File "/opt/conda/lib/python3.7/site-packages/wandb/sdk/interface/interface_shared.py", line 226, in _communicate
    return self._communicate_async(rec, local=local).get(timeout=timeout)
  File "/opt/conda/lib/python3.7/site-packages/wandb/sdk/interface/interface_shared.py", line 231, in _communicate_async
    raise Exception("The wandb backend process has shutdown")
