
  0%|          | 0/154 [00:00<?, ?it/s]
load pre-trained model :  /kaggle/working/multi_label/exp15_primary_label_add_background_noise/fold-0.pth
<All keys matched successfully>
#########################
#### Training
#### Fold: 1 | Image Size: (224, 313) | Model: tf_efficientnet_b1_ns | Batch Size: 128 | Scheduler: cos






















 20%|██        | 31/154 [02:18<05:15,  2.56s/it]
Traceback (most recent call last):
  File "/opt/conda/lib/python3.7/site-packages/IPython/core/interactiveshell.py", line 3552, in run_code
    exec(code_obj, self.user_global_ns, self.user_ns)
  File "/tmp/ipykernel_2275/2805150653.py", line 97, in <module>
    for batch_idx, (inputs, sample_info) in enumerate(tqdm(train_dataloader)):
  File "/opt/conda/lib/python3.7/site-packages/tqdm/std.py", line 1195, in __iter__
    for obj in iterable:
  File "/opt/conda/lib/python3.7/site-packages/torch/utils/data/dataloader.py", line 628, in __next__
    data = self._next_data()
  File "/opt/conda/lib/python3.7/site-packages/torch/utils/data/dataloader.py", line 1316, in _next_data
    idx, data = self._get_data()
  File "/opt/conda/lib/python3.7/site-packages/torch/utils/data/dataloader.py", line 1282, in _get_data
    success, data = self._try_get_data()
  File "/opt/conda/lib/python3.7/site-packages/torch/utils/data/dataloader.py", line 1120, in _try_get_data
    data = self._data_queue.get(timeout=timeout)
  File "/opt/conda/lib/python3.7/multiprocessing/queues.py", line 104, in get
    if not self._poll(timeout):
  File "/opt/conda/lib/python3.7/multiprocessing/connection.py", line 257, in poll
    return self._poll(timeout)
  File "/opt/conda/lib/python3.7/multiprocessing/connection.py", line 414, in _poll
    r = wait([self], timeout)
  File "/opt/conda/lib/python3.7/multiprocessing/connection.py", line 921, in wait
    ready = selector.select(timeout)
  File "/opt/conda/lib/python3.7/selectors.py", line 415, in select
    fd_event_list = self._selector.poll(timeout)
KeyboardInterrupt
During handling of the above exception, another exception occurred:
Traceback (most recent call last):
  File "/opt/conda/lib/python3.7/site-packages/IPython/core/interactiveshell.py", line 2098, in showtraceback
    stb = value._render_traceback_()
AttributeError: 'KeyboardInterrupt' object has no attribute '_render_traceback_'
During handling of the above exception, another exception occurred:
Traceback (most recent call last):
  File "/opt/conda/lib/python3.7/site-packages/IPython/core/ultratb.py", line 1101, in get_records
    return _fixed_getinnerframes(etb, number_of_lines_of_context, tb_offset)
  File "/opt/conda/lib/python3.7/site-packages/IPython/core/ultratb.py", line 248, in wrapped
    return f(*args, **kwargs)
  File "/opt/conda/lib/python3.7/site-packages/IPython/core/ultratb.py", line 281, in _fixed_getinnerframes
    records = fix_frame_records_filenames(inspect.getinnerframes(etb, context))
  File "/opt/conda/lib/python3.7/inspect.py", line 1502, in getinnerframes
    frameinfo = (tb.tb_frame,) + getframeinfo(tb, context)
  File "/opt/conda/lib/python3.7/inspect.py", line 1460, in getframeinfo
    filename = getsourcefile(frame) or getfile(frame)
  File "/opt/conda/lib/python3.7/inspect.py", line 696, in getsourcefile
    if getattr(getmodule(object, filename), '__loader__', None) is not None:
  File "/opt/conda/lib/python3.7/inspect.py", line 742, in getmodule
    os.path.realpath(f)] = module.__name__
  File "/opt/conda/lib/python3.7/posixpath.py", line 396, in realpath
    return abspath(path)
  File "/opt/conda/lib/python3.7/posixpath.py", line 385, in abspath
    return normpath(path)
  File "/opt/conda/lib/python3.7/posixpath.py", line 341, in normpath
    if isinstance(path, bytes):

 20%|██        | 31/154 [02:22<09:27,  4.61s/it]
Exception in thread NetStatThr:
Traceback (most recent call last):
  File "/opt/conda/lib/python3.7/threading.py", line 926, in _bootstrap_inner
    self.run()
  File "/opt/conda/lib/python3.7/threading.py", line 870, in run
    self._target(*self._args, **self._kwargs)
  File "/opt/conda/lib/python3.7/site-packages/wandb/sdk/wandb_run.py", line 152, in check_network_status
    status_response = self._interface.communicate_network_status()
  File "/opt/conda/lib/python3.7/site-packages/wandb/sdk/interface/interface.py", line 138, in communicate_network_status
    resp = self._communicate_network_status(status)
  File "/opt/conda/lib/python3.7/site-packages/wandb/sdk/interface/interface_shared.py", line 405, in _communicate_network_status
    resp = self._communicate(req, local=True)
  File "/opt/conda/lib/python3.7/site-packages/wandb/sdk/interface/interface_shared.py", line 226, in _communicate
    return self._communicate_async(rec, local=local).get(timeout=timeout)
  File "/opt/conda/lib/python3.7/site-packages/wandb/sdk/interface/interface_shared.py", line 231, in _communicate_async
    raise Exception("The wandb backend process has shutdown")
Exception: The wandb backend process has shutdown
Exception in thread ChkStopThr:
Traceback (most recent call last):
  File "/opt/conda/lib/python3.7/threading.py", line 926, in _bootstrap_inner
    self.run()
  File "/opt/conda/lib/python3.7/threading.py", line 870, in run
    self._target(*self._args, **self._kwargs)
  File "/opt/conda/lib/python3.7/site-packages/wandb/sdk/wandb_run.py", line 170, in check_status
    status_response = self._interface.communicate_stop_status()
  File "/opt/conda/lib/python3.7/site-packages/wandb/sdk/interface/interface.py", line 127, in communicate_stop_status
    resp = self._communicate_stop_status(status)
  File "/opt/conda/lib/python3.7/site-packages/wandb/sdk/interface/interface_shared.py", line 395, in _communicate_stop_status
    resp = self._communicate(req, local=True)
  File "/opt/conda/lib/python3.7/site-packages/wandb/sdk/interface/interface_shared.py", line 226, in _communicate
    return self._communicate_async(rec, local=local).get(timeout=timeout)
  File "/opt/conda/lib/python3.7/site-packages/wandb/sdk/interface/interface_shared.py", line 231, in _communicate_async
    raise Exception("The wandb backend process has shutdown")
