#########################
#### Training
#### Fold: 1 | Image Size: (224, 313) | Model: tf_efficientnet_b1_ns | Batch Size: 128 | Scheduler: cos
#### Num Train: 19,627 | Num Valid: 3,381


































































100%|██████████| 154/154 [02:18<00:00,  1.11it/s]









100%|██████████| 27/27 [00:22<00:00,  1.20it/s]
Epoch: 1 | Train Loss: 0.20460325385165679 | Val Loss: 0.008548895621465312 | Val Padded_cmAP : 0.4792503424856461


































































100%|██████████| 154/154 [02:17<00:00,  1.12it/s]









100%|██████████| 27/27 [00:22<00:00,  1.22it/s]
Epoch: 2 | Train Loss: 0.01503258774831117 | Val Loss: 0.00722728617903259 | Val Padded_cmAP : 0.4800268609660687



  4%|▍         | 6/154 [00:09<02:44,  1.11s/it]Exception ignored in: <function _MultiProcessingDataLoaderIter.__del__ at 0x7f9f26a0b320>
Traceback (most recent call last):
  File "/opt/conda/lib/python3.7/site-packages/torch/utils/data/dataloader.py", line 1466, in __del__
    self._shutdown_workers()
  File "/opt/conda/lib/python3.7/site-packages/torch/utils/data/dataloader.py", line 1430, in _shutdown_workers
    w.join(timeout=_utils.MP_STATUS_CHECK_INTERVAL)
  File "/opt/conda/lib/python3.7/multiprocessing/process.py", line 140, in join
    res = self._popen.wait(timeout)
  File "/opt/conda/lib/python3.7/multiprocessing/popen_fork.py", line 45, in wait
    if not wait([self.sentinel], timeout):
  File "/opt/conda/lib/python3.7/multiprocessing/connection.py", line 921, in wait
    ready = selector.select(timeout)
  File "/opt/conda/lib/python3.7/selectors.py", line 415, in select
    fd_event_list = self._selector.poll(timeout)
KeyboardInterrupt:
  4%|▍         | 6/154 [00:09<03:55,  1.59s/it]
Process wandb_internal:
Traceback (most recent call last):
  File "/opt/conda/lib/python3.7/multiprocessing/process.py", line 297, in _bootstrap
    self.run()
  File "/opt/conda/lib/python3.7/multiprocessing/process.py", line 99, in run
    self._target(*self._args, **self._kwargs)
  File "/opt/conda/lib/python3.7/site-packages/wandb/sdk/internal/internal.py", line 160, in wandb_internal
    thread.join()
  File "/opt/conda/lib/python3.7/threading.py", line 1044, in join
    self._wait_for_tstate_lock()
  File "/opt/conda/lib/python3.7/threading.py", line 1060, in _wait_for_tstate_lock
    elif lock.acquire(block, timeout):
KeyboardInterrupt
Traceback (most recent call last):
  File "<string>", line 1, in <module>
  File "/opt/conda/lib/python3.7/multiprocessing/spawn.py", line 105, in spawn_main
    exitcode = _main(fd)
  File "/opt/conda/lib/python3.7/multiprocessing/spawn.py", line 118, in _main
    return self._bootstrap()
  File "/opt/conda/lib/python3.7/multiprocessing/process.py", line 315, in _bootstrap
    threading._shutdown()
  File "/opt/conda/lib/python3.7/threading.py", line 1307, in _shutdown
    lock.acquire()
KeyboardInterrupt
Exception in thread NetStatThr:
Traceback (most recent call last):
  File "/opt/conda/lib/python3.7/threading.py", line 926, in _bootstrap_inner
    self.run()
  File "/opt/conda/lib/python3.7/threading.py", line 870, in run
    self._target(*self._args, **self._kwargs)
  File "/opt/conda/lib/python3.7/site-packages/wandb/sdk/wandb_run.py", line 152, in check_network_status
    status_response = self._interface.communicate_network_status()
  File "/opt/conda/lib/python3.7/site-packages/wandb/sdk/interface/interface.py", line 138, in communicate_network_status
    resp = self._communicate_network_status(status)
  File "/opt/conda/lib/python3.7/site-packages/wandb/sdk/interface/interface_shared.py", line 405, in _communicate_network_status
    resp = self._communicate(req, local=True)
  File "/opt/conda/lib/python3.7/site-packages/wandb/sdk/interface/interface_shared.py", line 226, in _communicate
    return self._communicate_async(rec, local=local).get(timeout=timeout)
  File "/opt/conda/lib/python3.7/site-packages/wandb/sdk/interface/interface_shared.py", line 231, in _communicate_async
    raise Exception("The wandb backend process has shutdown")
Exception: The wandb backend process has shutdown
Exception in thread ChkStopThr:
Traceback (most recent call last):
  File "/opt/conda/lib/python3.7/threading.py", line 926, in _bootstrap_inner
    self.run()
  File "/opt/conda/lib/python3.7/threading.py", line 870, in run
    self._target(*self._args, **self._kwargs)
  File "/opt/conda/lib/python3.7/site-packages/wandb/sdk/wandb_run.py", line 170, in check_status
    status_response = self._interface.communicate_stop_status()
  File "/opt/conda/lib/python3.7/site-packages/wandb/sdk/interface/interface.py", line 127, in communicate_stop_status
    resp = self._communicate_stop_status(status)
  File "/opt/conda/lib/python3.7/site-packages/wandb/sdk/interface/interface_shared.py", line 395, in _communicate_stop_status
    resp = self._communicate(req, local=True)
  File "/opt/conda/lib/python3.7/site-packages/wandb/sdk/interface/interface_shared.py", line 226, in _communicate
    return self._communicate_async(rec, local=local).get(timeout=timeout)
  File "/opt/conda/lib/python3.7/site-packages/wandb/sdk/interface/interface_shared.py", line 231, in _communicate_async
    raise Exception("The wandb backend process has shutdown")
