
  0%|          | 0/307 [00:00<?, ?it/s]
load pre-trained model :  /kaggle/working/pre-training/exp1_pre_attblock_fold-0_20230501_pretrained.pth
_IncompatibleKeys(missing_keys=['bn0.weight', 'bn0.bias', 'bn0.running_mean', 'bn0.running_var', 'bn0.num_batches_tracked', 'model.classifier.weight', 'model.classifier.bias', 'att_block.att.weight', 'att_block.att.bias', 'att_block.cla.weight', 'att_block.cla.bias'], unexpected_keys=['to_melspec_fn.spectrogram.window', 'to_melspec_fn.mel_scale.fb'])
#########################
#### Training
#### Fold: 1 | Image Size: (224, 313) | Model: tf_efficientnet_b1_ns | Batch Size: 64 | Scheduler: cos


  1%|▏         | 4/307 [00:10<08:50,  1.75s/it]Exception ignored in: <function _MultiProcessingDataLoaderIter.__del__ at 0x7fe1f8423560>
Traceback (most recent call last):
  File "/opt/conda/lib/python3.7/site-packages/torch/utils/data/dataloader.py", line 1466, in __del__
    self._shutdown_workers()
  File "/opt/conda/lib/python3.7/site-packages/torch/utils/data/dataloader.py", line 1430, in _shutdown_workers
    w.join(timeout=_utils.MP_STATUS_CHECK_INTERVAL)
  File "/opt/conda/lib/python3.7/multiprocessing/process.py", line 140, in join
    res = self._popen.wait(timeout)
  File "/opt/conda/lib/python3.7/multiprocessing/popen_fork.py", line 45, in wait
    if not wait([self.sentinel], timeout):
  File "/opt/conda/lib/python3.7/multiprocessing/connection.py", line 921, in wait
    ready = selector.select(timeout)
  File "/opt/conda/lib/python3.7/selectors.py", line 415, in select
    fd_event_list = self._selector.poll(timeout)
KeyboardInterrupt:
  1%|▏         | 4/307 [00:11<14:45,  2.92s/it]
Exception in thread NetStatThr:
Traceback (most recent call last):
  File "/opt/conda/lib/python3.7/threading.py", line 926, in _bootstrap_inner
    self.run()
  File "/opt/conda/lib/python3.7/threading.py", line 870, in run
    self._target(*self._args, **self._kwargs)
  File "/opt/conda/lib/python3.7/site-packages/wandb/sdk/wandb_run.py", line 152, in check_network_status
    status_response = self._interface.communicate_network_status()
  File "/opt/conda/lib/python3.7/site-packages/wandb/sdk/interface/interface.py", line 138, in communicate_network_status
    resp = self._communicate_network_status(status)
  File "/opt/conda/lib/python3.7/site-packages/wandb/sdk/interface/interface_shared.py", line 405, in _communicate_network_status
    resp = self._communicate(req, local=True)
  File "/opt/conda/lib/python3.7/site-packages/wandb/sdk/interface/interface_shared.py", line 226, in _communicate
    return self._communicate_async(rec, local=local).get(timeout=timeout)
  File "/opt/conda/lib/python3.7/site-packages/wandb/sdk/interface/interface_shared.py", line 231, in _communicate_async
    raise Exception("The wandb backend process has shutdown")
