
  0%|          | 0/154 [00:00<?, ?it/s]
load pre-trained model :  /kaggle/working/pre-training/exp1_pre_attblock_fold-0_20230501_pretrained.pth
_IncompatibleKeys(missing_keys=['bn0.weight', 'bn0.bias', 'bn0.running_mean', 'bn0.running_var', 'bn0.num_batches_tracked', 'model.classifier.weight', 'model.classifier.bias', 'att_block.att.weight', 'att_block.att.bias', 'att_block.cla.weight', 'att_block.cla.bias'], unexpected_keys=['to_melspec_fn.spectrogram.window', 'to_melspec_fn.mel_scale.fb'])
#########################
#### Training
#### Fold: 1 | Image Size: (224, 313) | Model: tf_efficientnet_b1_ns | Batch Size: 128 | Scheduler: cos






















































































100%|██████████| 154/154 [03:33<00:00,  1.38s/it]








 93%|█████████▎| 25/27 [00:28<00:01,  1.34it/s]
100%|██████████| 27/27 [00:28<00:00,  1.07s/it]



















































































100%|██████████| 154/154 [03:15<00:00,  1.27s/it]









 89%|████████▉ | 24/27 [00:26<00:02,  1.40it/s]
100%|██████████| 27/27 [00:28<00:00,  1.04s/it]




















































































100%|██████████| 154/154 [03:25<00:00,  1.33s/it]












100%|██████████| 27/27 [00:28<00:00,  1.07s/it]
Epoch: 3 | Train Loss: 0.6909475462003187 | Val Loss: 0.6909682662398727 | Val Padded_cmAP : 0.45318627561802466























































































100%|██████████| 154/154 [03:20<00:00,  1.30s/it]











100%|██████████| 27/27 [00:28<00:00,  1.07s/it]
Epoch: 4 | Train Loss: 0.6908640315780392 | Val Loss: 0.6908801749900535 | Val Padded_cmAP : 0.45286134835747954























































































100%|██████████| 154/154 [03:21<00:00,  1.31s/it]









 93%|█████████▎| 25/27 [00:27<00:01,  1.07it/s]
100%|██████████| 27/27 [00:28<00:00,  1.06s/it]























































































100%|██████████| 154/154 [03:15<00:00,  1.27s/it]








 89%|████████▉ | 24/27 [00:27<00:02,  1.43it/s]
100%|██████████| 27/27 [00:29<00:00,  1.08s/it]
  0%|          | 0/154 [00:00<?, ?it/s]
Traceback (most recent call last):
  File "/opt/conda/lib/python3.7/site-packages/IPython/core/interactiveshell.py", line 3552, in run_code
    exec(code_obj, self.user_global_ns, self.user_ns)
  File "/tmp/ipykernel_7457/2390640549.py", line 97, in <module>
    for batch_idx, (inputs, sample_info) in enumerate(tqdm(train_dataloader)):
  File "/opt/conda/lib/python3.7/site-packages/tqdm/std.py", line 1195, in __iter__
    for obj in iterable:
  File "/opt/conda/lib/python3.7/site-packages/torch/utils/data/dataloader.py", line 628, in __next__
    data = self._next_data()
  File "/opt/conda/lib/python3.7/site-packages/torch/utils/data/dataloader.py", line 1316, in _next_data
    idx, data = self._get_data()
  File "/opt/conda/lib/python3.7/site-packages/torch/utils/data/dataloader.py", line 1282, in _get_data
    success, data = self._try_get_data()
  File "/opt/conda/lib/python3.7/site-packages/torch/utils/data/dataloader.py", line 1120, in _try_get_data
    data = self._data_queue.get(timeout=timeout)
  File "/opt/conda/lib/python3.7/multiprocessing/queues.py", line 104, in get
    if not self._poll(timeout):
  File "/opt/conda/lib/python3.7/multiprocessing/connection.py", line 257, in poll
    return self._poll(timeout)
  File "/opt/conda/lib/python3.7/multiprocessing/connection.py", line 414, in _poll
    r = wait([self], timeout)
  File "/opt/conda/lib/python3.7/multiprocessing/connection.py", line 921, in wait
    ready = selector.select(timeout)
  File "/opt/conda/lib/python3.7/selectors.py", line 415, in select
    fd_event_list = self._selector.poll(timeout)
KeyboardInterrupt
During handling of the above exception, another exception occurred:
Traceback (most recent call last):
  File "/opt/conda/lib/python3.7/site-packages/IPython/core/interactiveshell.py", line 2098, in showtraceback
    stb = value._render_traceback_()
AttributeError: 'KeyboardInterrupt' object has no attribute '_render_traceback_'
During handling of the above exception, another exception occurred:
Traceback (most recent call last):
  File "/opt/conda/lib/python3.7/site-packages/IPython/core/ultratb.py", line 1101, in get_records
    return _fixed_getinnerframes(etb, number_of_lines_of_context, tb_offset)
  File "/opt/conda/lib/python3.7/site-packages/IPython/core/ultratb.py", line 248, in wrapped
    return f(*args, **kwargs)
  File "/opt/conda/lib/python3.7/site-packages/IPython/core/ultratb.py", line 281, in _fixed_getinnerframes
    records = fix_frame_records_filenames(inspect.getinnerframes(etb, context))
  File "/opt/conda/lib/python3.7/inspect.py", line 1502, in getinnerframes
    frameinfo = (tb.tb_frame,) + getframeinfo(tb, context)
  File "/opt/conda/lib/python3.7/inspect.py", line 1460, in getframeinfo
    filename = getsourcefile(frame) or getfile(frame)
  File "/opt/conda/lib/python3.7/inspect.py", line 696, in getsourcefile
    if getattr(getmodule(object, filename), '__loader__', None) is not None:
  File "/opt/conda/lib/python3.7/inspect.py", line 742, in getmodule
    os.path.realpath(f)] = module.__name__
  File "/opt/conda/lib/python3.7/posixpath.py", line 395, in realpath
    path, ok = _joinrealpath(filename[:0], filename, {})
  File "/opt/conda/lib/python3.7/posixpath.py", line 429, in _joinrealpath
    if not islink(newpath):
  File "/opt/conda/lib/python3.7/posixpath.py", line 171, in islink
    st = os.lstat(path)

  0%|          | 0/154 [00:04<?, ?it/s]
Exception in thread ChkStopThr:
Traceback (most recent call last):
  File "/opt/conda/lib/python3.7/threading.py", line 926, in _bootstrap_inner
    self.run()
  File "/opt/conda/lib/python3.7/threading.py", line 870, in run
    self._target(*self._args, **self._kwargs)
  File "/opt/conda/lib/python3.7/site-packages/wandb/sdk/wandb_run.py", line 170, in check_status
    status_response = self._interface.communicate_stop_status()
  File "/opt/conda/lib/python3.7/site-packages/wandb/sdk/interface/interface.py", line 127, in communicate_stop_status
    resp = self._communicate_stop_status(status)
  File "/opt/conda/lib/python3.7/site-packages/wandb/sdk/interface/interface_shared.py", line 395, in _communicate_stop_status
    resp = self._communicate(req, local=True)
  File "/opt/conda/lib/python3.7/site-packages/wandb/sdk/interface/interface_shared.py", line 226, in _communicate
    return self._communicate_async(rec, local=local).get(timeout=timeout)
  File "/opt/conda/lib/python3.7/site-packages/wandb/sdk/interface/interface_shared.py", line 231, in _communicate_async
    raise Exception("The wandb backend process has shutdown")
Exception: The wandb backend process has shutdown
Exception in thread NetStatThr:
Traceback (most recent call last):
  File "/opt/conda/lib/python3.7/threading.py", line 926, in _bootstrap_inner
    self.run()
  File "/opt/conda/lib/python3.7/threading.py", line 870, in run
    self._target(*self._args, **self._kwargs)
  File "/opt/conda/lib/python3.7/site-packages/wandb/sdk/wandb_run.py", line 152, in check_network_status
    status_response = self._interface.communicate_network_status()
  File "/opt/conda/lib/python3.7/site-packages/wandb/sdk/interface/interface.py", line 138, in communicate_network_status
    resp = self._communicate_network_status(status)
  File "/opt/conda/lib/python3.7/site-packages/wandb/sdk/interface/interface_shared.py", line 405, in _communicate_network_status
    resp = self._communicate(req, local=True)
  File "/opt/conda/lib/python3.7/site-packages/wandb/sdk/interface/interface_shared.py", line 226, in _communicate
    return self._communicate_async(rec, local=local).get(timeout=timeout)
  File "/opt/conda/lib/python3.7/site-packages/wandb/sdk/interface/interface_shared.py", line 231, in _communicate_async
    raise Exception("The wandb backend process has shutdown")
